Workbook

Sheet README
A1: Marketing review
A2: Your post log and review dashboard. Log each post on Posts; the Review sheet works everything out. Works in Excel (Mac or Windows), Apple Numbers and Google Sheets. A quick preview shows the gray columns, the Review sheet and its charts empty: open the file in the app (see Opening it, below).
A4: Start here
B5: The rows on Posts and Calendar are made-up examples, so you can see how it works. When you start your own log, select Posts A2:M25 and press Delete, then Calendar A2:G7. Leave the gray columns alone.
A7: Log a post
A8: 1 | B8: On Posts, go to the first empty row.
A9: 2 | B9: Type the date it went live, pick the platform and the song section, and paste the clip name and the post's link.
A10: 3 | B10: Length (s): how long the clip is, in seconds.
A11: 4 | B11: About a week later, fill in Views, Likes, Comments, Shares and Saves from the app's insights. Leave a box empty when the app doesn't show that number (YouTube shows no saves).
A12: 5 | B12: Trial reel: Yes for an Instagram trial reel, otherwise No.
B13: A row counts as a post once it has a date: a row without one stays out of the Review sheet.
A15: Clip names
B16: Use the file name Take Cutter gave the clip, like chorus-2_01m22s-01m41s. The times say where the take sits in the long rehearsal recording, so you can always find it again.
A18: Columns you type
A19: A Date | B19: The day the post went live.
A20: B Platform | B20: Instagram, TikTok or YouTube (pick from the list).
A21: C Clip | B21: The Take Cutter file name.
A22: D Section | B22: Which part of the song (pick from the list).
A23: E Link | B23: The post's web address.
A24: F Length (s) | B24: Clip length in seconds.
A25: G-K Views to Saves | B25: From the app's insights. Plain numbers: 1200, not 1.2k.
A26: L Trial reel | B26: Yes or No.
A27: M Notes | B27: Anything: the time you posted, the title, what you tried.
A29: Formula columns (gray: don't type in them)
A30: N Week | B30: Week number of the year; weeks start on Monday, and week 1 holds 1 January.
A31: O Length bucket | B31: 0–15 s, 15–25 s, 25–40 s or 40+ s.
A32: P Engagement | B32: Likes + comments + shares + saves.
A33: Q Engagement rate | B33: Engagement divided by views.
A34: R Rank | B34: 1 = most views, among the rows with a date. A tie goes to the post logged first.
B35: They are filled down to row 1000, so a new row just works. If you type over one by accident, copy the gray cell above it and paste it back.
A37: Length buckets
A38: 0–15 s | B38: Under 15 seconds.
A39: 15–25 s | B39: 15 up to 25 seconds. A clip of exactly 15 s lands here.
A40: 25–40 s | B40: 25 up to 40 seconds.
A41: 40+ s | B41: 40 seconds and longer.
B42: Change the cut-offs on the Lists sheet.
A44: Titles
B45: Shorts titles stop at 100 characters.
A47: The other sheets
A48: Review | B48: Views by platform, average views by length, your top 10 clips with links, the last 12 weeks, trial reels against main posts, and your best song sections. Nothing to type; it updates as you log.
...

Sheet Posts
A1: Date | B1: Platform | C1: Clip | D1: Section | E1: Link | F1: Length (s) | G1: Views | H1: Likes | I1: Comments | J1: Shares | K1: Saves | L1: Trial reel | M1: Notes | N1: Week | O1: Length bucket | P1: Engagement | Q1: Engagement rate | R1: Rank
A2: 46238 | B2: TikTok | C2: verse-1_03m10s-03m28s | D2: verse 1 | E2: https://www.tiktok.com/@yourhandle/video/0000000000000000001 | F2: 18 | G2: 2140 | H2: 161 | I2: 9 | J2: 12 | K2: 21 | L2: No | M2: First post of the song | N2: =IF(A2="","",WEEKNUM(A2,2)) | O2: =IF(OR(A2="",F2=""),"",LOOKUP(F2,Lists!$F$2:$F$5,Lists!$G$2:$G$5)) | P2: =IF(A2="","",SUM(H2:K2)) | Q2: =IF(A2="","",IFERROR(P2/G2,"")) | R2: =IF(OR(A2="",G2=""),"",COUNTIFS($N$2:$N$1000,">0",$G$2:$G$1000,">"&G2)+COUNTIFS($N$2:N2,">0",$G$2:G2,G2))
A3: 46238 | B3: Instagram | C3: verse-1_03m10s-03m28s | D3: verse 1 | E3: https://www.instagram.com/reel/placeholder02/ | F3: 18 | G3: 1630 | H3: 118 | I3: 6 | J3: 9 | K3: 17 | L3: No | N3: =IF(A3="","",WEEKNUM(A3,2)) | O3: =IF(OR(A3="",F3=""),"",LOOKUP(F3,Lists!$F$2:$F$5,Lists!$G$2:$G$5)) | P3: =IF(A3="","",SUM(H3:K3)) | Q3: =IF(A3="","",IFERROR(P3/G3,"")) | R3: =IF(OR(A3="",G3=""),"",COUNTIFS($N$2:$N$1000,">0",$G$2:$G$1000,">"&G3)+COUNTIFS($N$2:N3,">0",$G$2:G3,G3))
A4: 46239 | B4: YouTube | C4: verse-1_03m10s-03m28s | D4: verse 1 | E4: https://www.youtube.com/shorts/placeholder03 | F4: 18 | G4: 880 | H4: 41 | I4: 2 | J4: 3 | L4: No | M4: Title 64 characters | N4: =IF(A4="","",WEEKNUM(A4,2)) | O4: =IF(OR(A4="",F4=""),"",LOOKUP(F4,Lists!$F$2:$F$5,Lists!$G$2:$G$5)) | P4: =IF(A4="","",SUM(H4:K4)) | Q4: =IF(A4="","",IFERROR(P4/G4,"")) | R4: =IF(OR(A4="",G4=""),"",COUNTIFS($N$2:$N$1000,">0",$G$2:$G$1000,">"&G4)+COUNTIFS($N$2:N4,">0",$G$2:G4,G4))
A5: 46245 | B5: TikTok | C5: chorus-2_01m22s-01m41s | D5: chorus | E5: https://www.tiktok.com/@yourhandle/video/0000000000000000004 | F5: 19 | G5: 8420 | H5: 702 | I5: 38 | J5: 96 | K5: 131 | L5: No | M5: Posted at 7 pm | N5: =IF(A5="","",WEEKNUM(A5,2)) | O5: =IF(OR(A5="",F5=""),"",LOOKUP(F5,Lists!$F$2:$F$5,Lists!$G$2:$G$5)) | P5: =IF(A5="","",SUM(H5:K5)) | Q5: =IF(A5="","",IFERROR(P5/G5,"")) | R5: =IF(OR(A5="",G5=""),"",COUNTIFS($N$2:$N$1000,">0",$G$2:$G$1000,">"&G5)+COUNTIFS($N$2:N5,">0",$G$2:G5,G5))
A6: 46245 | B6: Instagram | C6: chorus-2_01m22s-01m41s | D6: chorus | E6: https://www.instagram.com/reel/placeholder05/ | F6: 19 | G6: 5210 | H6: 433 | I6: 21 | J6: 58 | K6: 88 | L6: No | N6: =IF(A6="","",WEEKNUM(A6,2)) | O6: =IF(OR(A6="",F6=""),"",LOOKUP(F6,Lists!$F$2:$F$5,Lists!$G$2:$G$5)) | P6: =IF(A6="","",SUM(H6:K6)) | Q6: =IF(A6="","",IFERROR(P6/G6,"")) | R6: =IF(OR(A6="",G6=""),"",COUNTIFS($N$2:$N$1000,">0",$G$2:$G$1000,">"&G6)+COUNTIFS($N$2:N6,">0",$G$2:G6,G6))
A7: 46246 | B7: YouTube | C7: chorus-2_01m22s-01m41s | D7: chorus | E7: https://www.youtube.com/shorts/placeholder06 | F7: 19 | G7: 3960 | H7: 214 | I7: 11 | J7: 19 | L7: No | N7: =IF(A7="","",WEEKNUM(A7,2)) | O7: =IF(OR(A7="",F7=""),"",LOOKUP(F7,Lists!$F$2:$F$5,Lists!$G$2:$G$5)) | P7: =IF(A7="","",SUM(H7:K7)) | Q7: =IF(A7="","",IFERROR(P7/G7,"")) | R7: =IF(OR(A7="",G7=""),"",COUNTIFS($N$2:$N$1000,">0",$G$2:$G$1000,">"&G7)+COUNTIFS($N$2:N7,">0",$G$2:G7,G7))
A8: 46252 | B8: TikTok | C8: intro_00m04s-00m17s | D8: intro | E8: https://www.tiktok.com/@yourhandle/video/0000000000000000007 | F8: 13 | G8: 1210 | H8: 84 | I8: 3 | J8: 5 | K8: 9 | L8: No | N8: =IF(A8="","",WEEKNUM(A8,2)) | O8: =IF(OR(A8="",F8=""),"",LOOKUP(F8,Lists!$F$2:$F$5,Lists!$G$2:$G$5)) | P8: =IF(A8="","",SUM(H8:K8)) | Q8: =IF(A8="","",IFERROR(P8/G8,"")) | R8: =IF(OR(A8="",G8=""),"",COUNTIFS($N$2:$N$1000,">0",$G$2:$G$1000,">"&G8)+COUNTIFS($N$2:N8,">0",$G$2:G8,G8))
A9: 46252 | B9: Instagram | C9: intro_00m04s-00m17s | D9: intro | E9: https://www.instagram.com/reel/placeholder08/ | F9: 13 | G9: 940 | H9: 61 | I9: 2 | J9: 4 | K9: 8 | L9: No | N9: =IF(A9="","",WEEKNUM(A9,2)) | O9: =IF(OR(A9="",F9=""),"",LOOKUP(F9,Lists!$F$2:$F$5,Lists!$G$2:$G$5)) | P9: =IF(A9="","",SUM(H9:K9)) | Q9: =IF(A9="","",IFERROR(P9/G9,"")) | R9: =IF(OR(A9="",G9=""),"",COUNTIFS($N$2:$N$1000,">0",$G$2:$G$1000,">"&G9)+COUNTIFS($N$2:N9,">0",$G$2:G9,G9))
A10: 46253 | B10: YouTube | C10: intro_00m04s-00m17s | D10: intro | E10: https://www.youtube.com/shorts/placeholder09 | F10: 13 | G10: 610 | H10: 22 | I10: 1 | J10: 1 | L10: No | N10: =IF(A10="","",WEEKNUM(A10,2)) | O10: =IF(OR(A10="",F10=""),"",LOOKUP(F10,Lists!$F$2:$F$5,Lists!$G$2:$G$5)) | P10: =IF(A10="","",SUM(H10:K10)) | Q10: =IF(A10="","",IFERROR(P10/G10,"")) | R10: =IF(OR(A10="",G10=""),"",COUNTIFS($N$2:$N$1000,">0",$G$2:$G$1000,">"&G10)+COUNTIFS($N$2:N10,">0",$G$2:G10,G10))
A11: 46259 | B11: Instagram | C11: bridge_27m40s-28m13s | D11: bridge | E11: https://www.instagram.com/reel/placeholder10/ | F11: 33 | G11: 3870 | H11: 297 | I11: 17 | J11: 31 | K11: 52 | L11: No | M11: Main post, two trial reels the same day | N11: =IF(A11="","",WEEKNUM(A11,2)) | O11: =IF(OR(A11="",F11=""),"",LOOKUP(F11,Lists!$F$2:$F$5,Lists!$G$2:$G$5)) | P11: =IF(A11="","",SUM(H11:K11)) | Q11: =IF(A11="","",IFERROR(P11/G11,"")) | R11: =IF(OR(A11="",G11=""),"",COUNTIFS($N$2:$N$1000,">0",$G$2:$G$1000,">"&G11)+COUNTIFS($N$2:N11,">0",$G$2:G11,G11))
A12: 46259 | B12: Instagram | C12: chorus-1_12m04s-12m16s | D12: chorus | E12: https://www.instagram.com/reel/placeholder11/ | F12: 12 | G12: 2650 | H12: 171 | I12: 5 | J12: 22 | K12: 30 | L12: Yes | M12: Trial reel A | N12: =IF(A12="","",WEEKNUM(A12,2)) | O12: =IF(OR(A12="",F12=""),"",LOOKUP(F12,Lists!$F$2:$F$5,Lists!$G$2:$G$5)) | P12: =IF(A12="","",SUM(H12:K12)) | Q12: =IF(A12="","",IFERROR(P12/G12,"")) | R12: =IF(OR(A12="",G12=""),"",COUNTIFS($N$2:$N$1000,">0",$G$2:$G$1000,">"&G12)+COUNTIFS($N$2:N12,">0",$G$2:G12,G12))
A13: 46259 | B13: Instagram | C13: pre-chorus_08m51s-09m13s | D13: pre-chorus | E13: https://www.instagram.com/reel/placeholder12/ | F13: 22 | G13: 4480 | H13: 356 | I13: 14 | J13: 47 | K13: 61 | L13: Yes | M13: Trial reel B | N13: =IF(A13="","",WEEKNUM(A13,2)) | O13: =IF(OR(A13="",F13=""),"",LOOKUP(F13,Lists!$F$2:$F$5,Lists!$G$2:$G$5)) | P13: =IF(A13="","",SUM(H13:K13)) | Q13: =IF(A13="","",IFERROR(P13/G13,"")) | R13: =IF(OR(A13="",G13=""),"",COUNTIFS($N$2:$N$1000,">0",$G$2:$G$1000,">"&G13)+COUNTIFS($N$2:N13,">0",$G$2:G13,G13))
A14: 46259 | B14: TikTok | C14: bridge_27m40s-28m13s | D14: bridge | E14: https://www.tiktok.com/@yourhandle/video/0000000000000000013 | F14: 33 | G14: 5930 | H14: 468 | I14: 26 | J14: 55 | K14: 83 | L14: No | N14: =IF(A14="","",WEEKNUM(A14,2)) | O14: =IF(OR(A14="",F14=""),"",LOOKUP(F14,Lists!$F$2:$F$5,Lists!$G$2:$G$5)) | P14: =IF(A14="","",SUM(H14:K14)) | Q14: =IF(A14="","",IFERROR(P14/G14,"")) | R14: =IF(OR(A14="",G14=""),"",COUNTIFS($N$2:$N$1000,">0",$G$2:$G$1000,">"&G14)+COUNTIFS($N$2:N14,">0",$G$2:G14,G14))
A15: 46260 | B15: YouTube | C15: bridge_27m40s-28m13s | D15: bridge | E15: https://www.youtube.com/shorts/placeholder14 | F15: 33 | G15: 9870 | H15: 512 | I15: 29 | J15: 41 | L15: No | M15: Picked up by the Shorts feed | N15: =IF(A15="","",WEEKNUM(A15,2)) | O15: =IF(OR(A15="",F15=""),"",LOOKUP(F15,Lists!$F$2:$F$5,Lists!$G$2:$G$5)) | P15: =IF(A15="","",SUM(H15:K15)) | Q15: =IF(A15="","",IFERROR(P15/G15,"")) | R15: =IF(OR(A15="",G15=""),"",COUNTIFS($N$2:$N$1000,">0",$G$2:$G$1000,">"&G15)+COUNTIFS($N$2:N15,">0",$G$2:G15,G15))
A16: 46266 | B16: TikTok | C16: verse-2_19m30s-19m52s | D16: verse 2 | E16: https://www.tiktok.com/@yourhandle/video/0000000000000000015 | F16: 22 | G16: 3350 | H16: 247 | I16: 12 | J16: 20 | K16: 34 | L16: No | N16: =IF(A16="","",WEEKNUM(A16,2)) | O16: =IF(OR(A16="",F16=""),"",LOOKUP(F16,Lists!$F$2:$F$5,Lists!$G$2:$G$5)) | P16: =IF(A16="","",SUM(H16:K16)) | Q16: =IF(A16="","",IFERROR(P16/G16,"")) | R16: =IF(OR(A16="",G16=""),"",COUNTIFS($N$2:$N$1000,">0",$G$2:$G$1000,">"&G16)+COUNTIFS($N$2:N16,">0",$G$2:G16,G16))
A17: 46266 | B17: Instagram | C17: verse-2_19m30s-19m52s | D17: verse 2 | E17: https://www.instagram.com/reel/placeholder16/ | F17: 22 | G17: 2080 | H17: 149 | I17: 7 | J17: 13 | K17: 22 | L17: No | N17: =IF(A17="","",WEEKNUM(A17,2)) | O17: =IF(OR(A17="",F17=""),"",LOOKUP(F17,Lists!$F$2:$F$5,Lists!$G$2:$G$5)) | P17: =IF(A17="","",SUM(H17:K17)) | Q17: =IF(A17="","",IFERROR(P17/G17,"")) | R17: =IF(OR(A17="",G17=""),"",COUNTIFS($N$2:$N$1000,">0",$G$2:$G$1000,">"&G17)+COUNTIFS($N$2:N17,">0",$G$2:G17,G17))
A18: 46273 | B18: TikTok | C18: outro_41m02s-41m49s | D18: outro | E18: https://www.tiktok.com/@yourhandle/video/0000000000000000017 | F18: 47 | G18: 1480 | H18: 92 | I18: 4 | J18: 6 | K18: 11 | L18: No | N18: =IF(A18="","",WEEKNUM(A18,2)) | O18: =IF(OR(A18="",F18=""),"",LOOKUP(F18,Lists!$F$2:$F$5,Lists!$G$2:$G$5)) | P18: =IF(A18="","",SUM(H18:K18)) | Q18: =IF(A18="","",IFERROR(P18/G18,"")) | R18: =IF(OR(A18="",G18=""),"",COUNTIFS($N$2:$N$1000,">0",$G$2:$G$1000,">"&G18)+COUNTIFS($N$2:N18,">0",$G$2:G18,G18))
A19: 46273 | B19: Instagram | C19: outro_41m02s-41m49s | D19: outro | E19: https://www.instagram.com/reel/placeholder18/ | F19: 47 | G19: 1210 | H19: 70 | I19: 3 | J19: 5 | K19: 9 | L19: No | M19: Same views as the intro TikTok | N19: =IF(A19="","",WEEKNUM(A19,2)) | O19: =IF(OR(A19="",F19=""),"",LOOKUP(F19,Lists!$F$2:$F$5,Lists!$G$2:$G$5)) | P19: =IF(A19="","",SUM(H19:K19)) | Q19: =IF(A19="","",IFERROR(P19/G19,"")) | R19: =IF(OR(A19="",G19=""),"",COUNTIFS($N$2:$N$1000,">0",$G$2:$G$1000,">"&G19)+COUNTIFS($N$2:N19,">0",$G$2:G19,G19))
A20: 46274 | B20: YouTube | C20: outro_41m02s-41m49s | D20: outro | E20: https://www.youtube.com/shorts/placeholder19 | F20: 47 | G20: 690 | H20: 28 | I20: 1 | J20: 2 | L20: No | N20: =IF(A20="","",WEEKNUM(A20,2)) | O20: =IF(OR(A20="",F20=""),"",LOOKUP(F20,Lists!$F$2:$F$5,Lists!$G$2:$G$5)) | P20: =IF(A20="","",SUM(H20:K20)) | Q20: =IF(A20="","",IFERROR(P20/G20,"")) | R20: =IF(OR(A20="",G20=""),"",COUNTIFS($N$2:$N$1000,">0",$G$2:$G$1000,">"&G20)+COUNTIFS($N$2:N20,">0",$G$2:G20,G20))
A21: 46280 | B21: TikTok | C21: chorus-3_33m15s-33m39s | D21: chorus | E21: https://www.tiktok.com/@yourhandle/video/0000000000000000020 | F21: 24 | G21: 12650 | H21: 1104 | I21: 57 | J21: 163 | K21: 214 | L21: No | M21: Best hook so far | N21: =IF(A21="","",WEEKNUM(A21,2)) | O21: =IF(OR(A21="",F21=""),"",LOOKUP(F21,Lists!$F$2:$F$5,Lists!$G$2:$G$5)) | P21: =IF(A21="","",SUM(H21:K21)) | Q21: =IF(A21="","",IFERROR(P21/G21,"")) | R21: =IF(OR(A21="",G21=""),"",COUNTIFS($N$2:$N$1000,">0",$G$2:$G$1000,">"&G21)+COUNTIFS($N$2:N21,">0",$G$2:G21,G21))
A22: 46280 | B22: Instagram | C22: chorus-3_33m15s-33m39s | D22: chorus | E22: https://www.instagram.com/reel/placeholder21/ | F22: 24 | G22: 7340 | H22: 618 | I22: 31 | J22: 84 | K22: 117 | L22: No | N22: =IF(A22="","",WEEKNUM(A22,2)) | O22: =IF(OR(A22="",F22=""),"",LOOKUP(F22,Lists!$F$2:$F$5,Lists!$G$2:$G$5)) | P22: =IF(A22="","",SUM(H22:K22)) | Q22: =IF(A22="","",IFERROR(P22/G22,"")) | R22: =IF(OR(A22="",G22=""),"",COUNTIFS($N$2:$N$1000,">0",$G$2:$G$1000,">"&G22)+COUNTIFS($N$2:N22,">0",$G$2:G22,G22))
A23: 46287 | B23: TikTok | C23: pre-chorus_08m51s-09m13s | D23: pre-chorus | E23: https://www.tiktok.com/@yourhandle/video/0000000000000000022 | F23: 22 | G23: 4120 | H23: 318 | I23: 15 | J23: 36 | K23: 49 | L23: No | M23: Trial reel B, now a main post | N23: =IF(A23="","",WEEKNUM(A23,2)) | O23: =IF(OR(A23="",F23=""),"",LOOKUP(F23,Lists!$F$2:$F$5,Lists!$G$2:$G$5)) | P23: =IF(A23="","",SUM(H23:K23)) | Q23: =IF(A23="","",IFERROR(P23/G23,"")) | R23: =IF(OR(A23="",G23=""),"",COUNTIFS($N$2:$N$1000,">0",$G$2:$G$1000,">"&G23)+COUNTIFS($N$2:N23,">0",$G$2:G23,G23))
A24: 46287 | B24: Instagram | C24: pre-chorus_08m51s-09m13s | D24: pre-chorus | E24: https://www.instagram.com/reel/placeholder23/ | F24: 22 | G24: 2960 | H24: 224 | I24: 10 | J24: 27 | K24: 38 | L24: No | N24: =IF(A24="","",WEEKNUM(A24,2)) | O24: =IF(OR(A24="",F24=""),"",LOOKUP(F24,Lists!$F$2:$F$5,Lists!$G$2:$G$5)) | P24: =IF(A24="","",SUM(H24:K24)) | Q24: =IF(A24="","",IFERROR(P24/G24,"")) | R24: =IF(OR(A24="",G24=""),"",COUNTIFS($N$2:$N$1000,">0",$G$2:$G$1000,">"&G24)+COUNTIFS($N$2:N24,">0",$G$2:G24,G24))
A25: 46289 | B25: YouTube | C25: pre-chorus_08m51s-09m13s | D25: pre-chorus | E25: https://www.youtube.com/shorts/placeholder24 | F25: 22 | L25: No | M25: Fill in the numbers after a week | N25: =IF(A25="","",WEEKNUM(A25,2)) | O25: =IF(OR(A25="",F25=""),"",LOOKUP(F25,Lists!$F$2:$F$5,Lists!$G$2:$G$5)) | P25: =IF(A25="","",SUM(H25:K25)) | Q25: =IF(A25="","",IFERROR(P25/G25,"")) | R25: =IF(OR(A25="",G25=""),"",COUNTIFS($N$2:$N$1000,">0",$G$2:$G$1000,">"&G25)+COUNTIFS($N$2:N25,">0",$G$2:G25,G25))
N26: =IF(A26="","",WEEKNUM(A26,2)) | O26: =IF(OR(A26="",F26=""),"",LOOKUP(F26,Lists!$F$2:$F$5,Lists!$G$2:$G$5)) | P26: =IF(A26="","",SUM(H26:K26)) | Q26: =IF(A26="","",IFERROR(P26/G26,"")) | R26: =IF(OR(A26="",G26=""),"",COUNTIFS($N$2:$N$1000,">0",$G$2:$G$1000,">"&G26)+COUNTIFS($N$2:N26,">0",$G$2:G26,G26))
N27: =IF(A27="","",WEEKNUM(A27,2)) | O27: =IF(OR(A27="",F27=""),"",LOOKUP(F27,Lists!$F$2:$F$5,Lists!$G$2:$G$5)) | P27: =IF(A27="","",SUM(H27:K27)) | Q27: =IF(A27="","",IFERROR(P27/G27,"")) | R27: =IF(OR(A27="",G27=""),"",COUNTIFS($N$2:$N$1000,">0",$G$2:$G$1000,">"&G27)+COUNTIFS($N$2:N27,">0",$G$2:G27,G27))
N28: =IF(A28="","",WEEKNUM(A28,2)) | O28: =IF(OR(A28="",F28=""),"",LOOKUP(F28,Lists!$F$2:$F$5,Lists!$G$2:$G$5)) | P28: =IF(A28="","",SUM(H28:K28)) | Q28: =IF(A28="","",IFERROR(P28/G28,"")) | R28: =IF(OR(A28="",G28=""),"",COUNTIFS($N$2:$N$1000,">0",$G$2:$G$1000,">"&G28)+COUNTIFS($N$2:N28,">0",$G$2:G28,G28))
N29: =IF(A29="","",WEEKNUM(A29,2)) | O29: =IF(OR(A29="",F29=""),"",LOOKUP(F29,Lists!$F$2:$F$5,Lists!$G$2:$G$5)) | P29: =IF(A29="","",SUM(H29:K29)) | Q29: =IF(A29="","",IFERROR(P29/G29,"")) | R29: =IF(OR(A29="",G29=""),"",COUNTIFS($N$2:$N$1000,">0",$G$2:$G$1000,">"&G29)+COUNTIFS($N$2:N29,">0",$G$2:G29,G29))
N30: =IF(A30="","",WEEKNUM(A30,2)) | O30: =IF(OR(A30="",F30=""),"",LOOKUP(F30,Lists!$F$2:$F$5,Lists!$G$2:$G$5)) | P30: =IF(A30="","",SUM(H30:K30)) | Q30: =IF(A30="","",IFERROR(P30/G30,"")) | R30: =IF(OR(A30="",G30=""),"",COUNTIFS($N$2:$N$1000,">0",$G$2:$G$1000,">"&G30)+COUNTIFS($N$2:N30,">0",$G$2:G30,G30))
N31: =IF(A31="","",WEEKNUM(A31,2)) | O31: =IF(OR(A31="",F31=""),"",LOOKUP(F31,Lists!$F$2:$F$5,Lists!$G$2:$G$5)) | P31: =IF(A31="","",SUM(H31:K31)) | Q31: =IF(A31="","",IFERROR(P31/G31,"")) | R31: =IF(OR(A31="",G31=""),"",COUNTIFS($N$2:$N$1000,">0",$G$2:$G$1000,">"&G31)+COUNTIFS($N$2:N31,">0",$G$2:G31,G31))
N32: =IF(A32="","",WEEKNUM(A32,2)) | O32: =IF(OR(A32="",F32=""),"",LOOKUP(F32,Lists!$F$2:$F$5,Lists!$G$2:$G$5)) | P32: =IF(A32="","",SUM(H32:K32)) | Q32: =IF(A32="","",IFERROR(P32/G32,"")) | R32: =IF(OR(A32="",G32=""),"",COUNTIFS($N$2:$N$1000,">0",$G$2:$G$1000,">"&G32)+COUNTIFS($N$2:N32,">0",$G$2:G32,G32))
N33: =IF(A33="","",WEEKNUM(A33,2)) | O33: =IF(OR(A33="",F33=""),"",LOOKUP(F33,Lists!$F$2:$F$5,Lists!$G$2:$G$5)) | P33: =IF(A33="","",SUM(H33:K33)) | Q33: =IF(A33="","",IFERROR(P33/G33,"")) | R33: =IF(OR(A33="",G33=""),"",COUNTIFS($N$2:$N$1000,">0",$G$2:$G$1000,">"&G33)+COUNTIFS($N$2:N33,">0",$G$2:G33,G33))
N34: =IF(A34="","",WEEKNUM(A34,2)) | O34: =IF(OR(A34="",F34=""),"",LOOKUP(F34,Lists!$F$2:$F$5,Lists!$G$2:$G$5)) | P34: =IF(A34="","",SUM(H34:K34)) | Q34: =IF(A34="","",IFERROR(P34/G34,"")) | R34: =IF(OR(A34="",G34=""),"",COUNTIFS($N$2:$N$1000,">0",$G$2:$G$1000,">"&G34)+COUNTIFS($N$2:N34,">0",$G$2:G34,G34))
N35: =IF(A35="","",WEEKNUM(A35,2)) | O35: =IF(OR(A35="",F35=""),"",LOOKUP(F35,Lists!$F$2:$F$5,Lists!$G$2:$G$5)) | P35: =IF(A35="","",SUM(H35:K35)) | Q35: =IF(A35="","",IFERROR(P35/G35,"")) | R35: =IF(OR(A35="",G35=""),"",COUNTIFS($N$2:$N$1000,">0",$G$2:$G$1000,">"&G35)+COUNTIFS($N$2:N35,">0",$G$2:G35,G35))
N36: =IF(A36="","",WEEKNUM(A36,2)) | O36: =IF(OR(A36="",F36=""),"",LOOKUP(F36,Lists!$F$2:$F$5,Lists!$G$2:$G$5)) | P36: =IF(A36="","",SUM(H36:K36)) | Q36: =IF(A36="","",IFERROR(P36/G36,"")) | R36: =IF(OR(A36="",G36=""),"",COUNTIFS($N$2:$N$1000,">0",$G$2:$G$1000,">"&G36)+COUNTIFS($N$2:N36,">0",$G$2:G36,G36))
N37: =IF(A37="","",WEEKNUM(A37,2)) | O37: =IF(OR(A37="",F37=""),"",LOOKUP(F37,Lists!$F$2:$F$5,Lists!$G$2:$G$5)) | P37: =IF(A37="","",SUM(H37:K37)) | Q37: =IF(A37="","",IFERROR(P37/G37,"")) | R37: =IF(OR(A37="",G37=""),"",COUNTIFS($N$2:$N$1000,">0",$G$2:$G$1000,">"&G37)+COUNTIFS($N$2:N37,">0",$G$2:G37,G37))
... N1000: =IF(A1000="","",WEEKNUM(A1000,2)) | O1000: =IF(OR(A1000="",F1000=""),"",LOOKUP(F1000,Lists!$F$2:$F$5,Lists!$G$2:$G$5)) | P1000: =IF(A1000="","",SUM(H1000:K1000)) | Q1000: =IF(A1000="","",IFERROR(P1000/G1000,"")) | R1000: =IF(OR(A1000="",G1000=""),"",COUNTIFS($N$2:$N$1000,">0",$G$2:$G$1000,">"&G1000)+COUNTIFS($N$2:N1000,">0",$G$2:G1000,G1000))

Sheet Review
B1: Marketing review
B2: Worked out from the Posts sheet as you log. Nothing to type on this page.
B4: At a glance
B5: Posts logged | C5: =COUNTIFS(Posts!$N$2:$N$1000,">0")
B6: Total views | C6: =SUMIFS(Posts!$G$2:$G$1000,Posts!$N$2:$N$1000,">0")
B7: Average views per post | C7: =IFERROR(AVERAGEIFS(Posts!$G$2:$G$1000,Posts!$N$2:$N$1000,">0"),"")
B8: Engagement rate | C8: =IFERROR(SUMIFS(Posts!$P$2:$P$1000,Posts!$N$2:$N$1000,">0",Posts!$G$2:$G$1000,">0")/SUMIFS(Posts!$G$2:$G$1000,Posts!$N$2:$N$1000,">0"),"")
B9: Best platform (average views) | C9: =IFERROR(INDEX($B$15:$B$17,MATCH(MAX($E$15:$E$17),$E$15:$E$17,0)),"")
B10: Best length (average views) | C10: =IFERROR(INDEX($B$31:$B$34,MATCH(MAX($D$31:$D$34),$D$31:$D$34,0)),"")
B11: Best song section (average views) | C11: =IFERROR(INDEX($B$83:$B$89,MATCH(MAX($E$83:$E$89),$E$83:$E$89,0)),"")
B13: Views by platform
B14: Platform | C14: Posts | D14: Views | E14: Avg views | F14: Engagement rate | G14: Share of views
B15: =Lists!$A$2 | C15: =COUNTIFS(Posts!$N$2:$N$1000,">0",Posts!$B$2:$B$1000,$B15) | D15: =SUMIFS(Posts!$G$2:$G$1000,Posts!$N$2:$N$1000,">0",Posts!$B$2:$B$1000,$B15) | E15: =IFERROR(AVERAGEIFS(Posts!$G$2:$G$1000,Posts!$N$2:$N$1000,">0",Posts!$B$2:$B$1000,$B15),"") | F15: =IFERROR(SUMIFS(Posts!$P$2:$P$1000,Posts!$N$2:$N$1000,">0",Posts!$B$2:$B$1000,$B15,Posts!$G$2:$G$1000,">0")/D15,"") | G15: =IFERROR(D15/$D$19,"")
B16: =Lists!$A$3 | C16: =COUNTIFS(Posts!$N$2:$N$1000,">0",Posts!$B$2:$B$1000,$B16) | D16: =SUMIFS(Posts!$G$2:$G$1000,Posts!$N$2:$N$1000,">0",Posts!$B$2:$B$1000,$B16) | E16: =IFERROR(AVERAGEIFS(Posts!$G$2:$G$1000,Posts!$N$2:$N$1000,">0",Posts!$B$2:$B$1000,$B16),"") | F16: =IFERROR(SUMIFS(Posts!$P$2:$P$1000,Posts!$N$2:$N$1000,">0",Posts!$B$2:$B$1000,$B16,Posts!$G$2:$G$1000,">0")/D16,"") | G16: =IFERROR(D16/$D$19,"")
B17: =Lists!$A$4 | C17: =COUNTIFS(Posts!$N$2:$N$1000,">0",Posts!$B$2:$B$1000,$B17) | D17: =SUMIFS(Posts!$G$2:$G$1000,Posts!$N$2:$N$1000,">0",Posts!$B$2:$B$1000,$B17) | E17: =IFERROR(AVERAGEIFS(Posts!$G$2:$G$1000,Posts!$N$2:$N$1000,">0",Posts!$B$2:$B$1000,$B17),"") | F17: =IFERROR(SUMIFS(Posts!$P$2:$P$1000,Posts!$N$2:$N$1000,">0",Posts!$B$2:$B$1000,$B17,Posts!$G$2:$G$1000,">0")/D17,"") | G17: =IFERROR(D17/$D$19,"")
B18: =IF(C18="","","Other or no platform") | C18: =IF(COUNTIFS(Posts!$N$2:$N$1000,">0")=SUM(C15:C17),"",COUNTIFS(Posts!$N$2:$N$1000,">0")-SUM(C15:C17)) | D18: =IF(C18="","",SUMIFS(Posts!$G$2:$G$1000,Posts!$N$2:$N$1000,">0")-SUM(D15:D17)) | G18: =IF(C18="","",IFERROR(D18/$D$19,""))
B19: All platforms | C19: =SUM(C15:C18) | D19: =SUM(D15:D18) | E19: =IFERROR(AVERAGEIFS(Posts!$G$2:$G$1000,Posts!$N$2:$N$1000,">0"),"") | F19: =C8 | G19: =IFERROR(D19/$D$19,"")
B28: Average views by length
B29: A clip of exactly 15 s counts as 15–25 s. The cut-offs live on the Lists sheet.
B30: Length | C30: Posts | D30: Avg views | E30: Engagement rate
B31: =Lists!$G$2 | C31: =COUNTIFS(Posts!$N$2:$N$1000,">0",Posts!$O$2:$O$1000,$B31) | D31: =IFERROR(AVERAGEIFS(Posts!$G$2:$G$1000,Posts!$N$2:$N$1000,">0",Posts!$O$2:$O$1000,$B31),"") | E31: =IFERROR(SUMIFS(Posts!$P$2:$P$1000,Posts!$N$2:$N$1000,">0",Posts!$O$2:$O$1000,$B31,Posts!$G$2:$G$1000,">0")/SUMIFS(Posts!$G$2:$G$1000,Posts!$N$2:$N$1000,">0",Posts!$O$2:$O$1000,$B31),"")
B32: =Lists!$G$3 | C32: =COUNTIFS(Posts!$N$2:$N$1000,">0",Posts!$O$2:$O$1000,$B32) | D32: =IFERROR(AVERAGEIFS(Posts!$G$2:$G$1000,Posts!$N$2:$N$1000,">0",Posts!$O$2:$O$1000,$B32),"") | E32: =IFERROR(SUMIFS(Posts!$P$2:$P$1000,Posts!$N$2:$N$1000,">0",Posts!$O$2:$O$1000,$B32,Posts!$G$2:$G$1000,">0")/SUMIFS(Posts!$G$2:$G$1000,Posts!$N$2:$N$1000,">0",Posts!$O$2:$O$1000,$B32),"")
B33: =Lists!$G$4 | C33: =COUNTIFS(Posts!$N$2:$N$1000,">0",Posts!$O$2:$O$1000,$B33) | D33: =IFERROR(AVERAGEIFS(Posts!$G$2:$G$1000,Posts!$N$2:$N$1000,">0",Posts!$O$2:$O$1000,$B33),"") | E33: =IFERROR(SUMIFS(Posts!$P$2:$P$1000,Posts!$N$2:$N$1000,">0",Posts!$O$2:$O$1000,$B33,Posts!$G$2:$G$1000,">0")/SUMIFS(Posts!$G$2:$G$1000,Posts!$N$2:$N$1000,">0",Posts!$O$2:$O$1000,$B33),"")
B34: =Lists!$G$5 | C34: =COUNTIFS(Posts!$N$2:$N$1000,">0",Posts!$O$2:$O$1000,$B34) | D34: =IFERROR(AVERAGEIFS(Posts!$G$2:$G$1000,Posts!$N$2:$N$1000,">0",Posts!$O$2:$O$1000,$B34),"") | E34: =IFERROR(SUMIFS(Posts!$P$2:$P$1000,Posts!$N$2:$N$1000,">0",Posts!$O$2:$O$1000,$B34,Posts!$G$2:$G$1000,">0")/SUMIFS(Posts!$G$2:$G$1000,Posts!$N$2:$N$1000,">0",Posts!$O$2:$O$1000,$B34),"")
B43: Top 10 clips
B44: Most views first. Ties go to the post logged first.
A45: # | B45: Clip | C45: Platform | D45: Section | E45: Length (s) | F45: Views | G45: Link
A46: 1 | B46: =IFERROR(INDEX(Posts!$C$2:$C$1000,MATCH($A46,Posts!$R$2:$R$1000,0))&"","") | C46: =IFERROR(INDEX(Posts!$B$2:$B$1000,MATCH($A46,Posts!$R$2:$R$1000,0))&"","") | D46: =IFERROR(INDEX(Posts!$D$2:$D$1000,MATCH($A46,Posts!$R$2:$R$1000,0))&"","") | E46: =IFERROR(IF(INDEX(Posts!$F$2:$F$1000,MATCH($A46,Posts!$R$2:$R$1000,0))="","",INDEX(Posts!$F$2:$F$1000,MATCH($A46,Posts!$R$2:$R$1000,0))),"") | F46: =IFERROR(INDEX(Posts!$G$2:$G$1000,MATCH($A46,Posts!$R$2:$R$1000,0)),"") | G46: =IFERROR(IF(INDEX(Posts!$E$2:$E$1000,MATCH($A46,Posts!$R$2:$R$1000,0))="","",HYPERLINK(INDEX(Posts!$E$2:$E$1000,MATCH($A46,Posts!$R$2:$R$1000,0)))),"")
A47: 2 | B47: =IFERROR(INDEX(Posts!$C$2:$C$1000,MATCH($A47,Posts!$R$2:$R$1000,0))&"","") | C47: =IFERROR(INDEX(Posts!$B$2:$B$1000,MATCH($A47,Posts!$R$2:$R$1000,0))&"","") | D47: =IFERROR(INDEX(Posts!$D$2:$D$1000,MATCH($A47,Posts!$R$2:$R$1000,0))&"","") | E47: =IFERROR(IF(INDEX(Posts!$F$2:$F$1000,MATCH($A47,Posts!$R$2:$R$1000,0))="","",INDEX(Posts!$F$2:$F$1000,MATCH($A47,Posts!$R$2:$R$1000,0))),"") | F47: =IFERROR(INDEX(Posts!$G$2:$G$1000,MATCH($A47,Posts!$R$2:$R$1000,0)),"") | G47: =IFERROR(IF(INDEX(Posts!$E$2:$E$1000,MATCH($A47,Posts!$R$2:$R$1000,0))="","",HYPERLINK(INDEX(Posts!$E$2:$E$1000,MATCH($A47,Posts!$R$2:$R$1000,0)))),"")
A48: 3 | B48: =IFERROR(INDEX(Posts!$C$2:$C$1000,MATCH($A48,Posts!$R$2:$R$1000,0))&"","") | C48: =IFERROR(INDEX(Posts!$B$2:$B$1000,MATCH($A48,Posts!$R$2:$R$1000,0))&"","") | D48: =IFERROR(INDEX(Posts!$D$2:$D$1000,MATCH($A48,Posts!$R$2:$R$1000,0))&"","") | E48: =IFERROR(IF(INDEX(Posts!$F$2:$F$1000,MATCH($A48,Posts!$R$2:$R$1000,0))="","",INDEX(Posts!$F$2:$F$1000,MATCH($A48,Posts!$R$2:$R$1000,0))),"") | F48: =IFERROR(INDEX(Posts!$G$2:$G$1000,MATCH($A48,Posts!$R$2:$R$1000,0)),"") | G48: =IFERROR(IF(INDEX(Posts!$E$2:$E$1000,MATCH($A48,Posts!$R$2:$R$1000,0))="","",HYPERLINK(INDEX(Posts!$E$2:$E$1000,MATCH($A48,Posts!$R$2:$R$1000,0)))),"")
A49: 4 | B49: =IFERROR(INDEX(Posts!$C$2:$C$1000,MATCH($A49,Posts!$R$2:$R$1000,0))&"","") | C49: =IFERROR(INDEX(Posts!$B$2:$B$1000,MATCH($A49,Posts!$R$2:$R$1000,0))&"","") | D49: =IFERROR(INDEX(Posts!$D$2:$D$1000,MATCH($A49,Posts!$R$2:$R$1000,0))&"","") | E49: =IFERROR(IF(INDEX(Posts!$F$2:$F$1000,MATCH($A49,Posts!$R$2:$R$1000,0))="","",INDEX(Posts!$F$2:$F$1000,MATCH($A49,Posts!$R$2:$R$1000,0))),"") | F49: =IFERROR(INDEX(Posts!$G$2:$G$1000,MATCH($A49,Posts!$R$2:$R$1000,0)),"") | G49: =IFERROR(IF(INDEX(Posts!$E$2:$E$1000,MATCH($A49,Posts!$R$2:$R$1000,0))="","",HYPERLINK(INDEX(Posts!$E$2:$E$1000,MATCH($A49,Posts!$R$2:$R$1000,0)))),"")
A50: 5 | B50: =IFERROR(INDEX(Posts!$C$2:$C$1000,MATCH($A50,Posts!$R$2:$R$1000,0))&"","") | C50: =IFERROR(INDEX(Posts!$B$2:$B$1000,MATCH($A50,Posts!$R$2:$R$1000,0))&"","") | D50: =IFERROR(INDEX(Posts!$D$2:$D$1000,MATCH($A50,Posts!$R$2:$R$1000,0))&"","") | E50: =IFERROR(IF(INDEX(Posts!$F$2:$F$1000,MATCH($A50,Posts!$R$2:$R$1000,0))="","",INDEX(Posts!$F$2:$F$1000,MATCH($A50,Posts!$R$2:$R$1000,0))),"") | F50: =IFERROR(INDEX(Posts!$G$2:$G$1000,MATCH($A50,Posts!$R$2:$R$1000,0)),"") | G50: =IFERROR(IF(INDEX(Posts!$E$2:$E$1000,MATCH($A50,Posts!$R$2:$R$1000,0))="","",HYPERLINK(INDEX(Posts!$E$2:$E$1000,MATCH($A50,Posts!$R$2:$R$1000,0)))),"")
A51: 6 | B51: =IFERROR(INDEX(Posts!$C$2:$C$1000,MATCH($A51,Posts!$R$2:$R$1000,0))&"","") | C51: =IFERROR(INDEX(Posts!$B$2:$B$1000,MATCH($A51,Posts!$R$2:$R$1000,0))&"","") | D51: =IFERROR(INDEX(Posts!$D$2:$D$1000,MATCH($A51,Posts!$R$2:$R$1000,0))&"","") | E51: =IFERROR(IF(INDEX(Posts!$F$2:$F$1000,MATCH($A51,Posts!$R$2:$R$1000,0))="","",INDEX(Posts!$F$2:$F$1000,MATCH($A51,Posts!$R$2:$R$1000,0))),"") | F51: =IFERROR(INDEX(Posts!$G$2:$G$1000,MATCH($A51,Posts!$R$2:$R$1000,0)),"") | G51: =IFERROR(IF(INDEX(Posts!$E$2:$E$1000,MATCH($A51,Posts!$R$2:$R$1000,0))="","",HYPERLINK(INDEX(Posts!$E$2:$E$1000,MATCH($A51,Posts!$R$2:$R$1000,0)))),"")
A52: 7 | B52: =IFERROR(INDEX(Posts!$C$2:$C$1000,MATCH($A52,Posts!$R$2:$R$1000,0))&"","") | C52: =IFERROR(INDEX(Posts!$B$2:$B$1000,MATCH($A52,Posts!$R$2:$R$1000,0))&"","") | D52: =IFERROR(INDEX(Posts!$D$2:$D$1000,MATCH($A52,Posts!$R$2:$R$1000,0))&"","") | E52: =IFERROR(IF(INDEX(Posts!$F$2:$F$1000,MATCH($A52,Posts!$R$2:$R$1000,0))="","",INDEX(Posts!$F$2:$F$1000,MATCH($A52,Posts!$R$2:$R$1000,0))),"") | F52: =IFERROR(INDEX(Posts!$G$2:$G$1000,MATCH($A52,Posts!$R$2:$R$1000,0)),"") | G52: =IFERROR(IF(INDEX(Posts!$E$2:$E$1000,MATCH($A52,Posts!$R$2:$R$1000,0))="","",HYPERLINK(INDEX(Posts!$E$2:$E$1000,MATCH($A52,Posts!$R$2:$R$1000,0)))),"")
A53: 8 | B53: =IFERROR(INDEX(Posts!$C$2:$C$1000,MATCH($A53,Posts!$R$2:$R$1000,0))&"","") | C53: =IFERROR(INDEX(Posts!$B$2:$B$1000,MATCH($A53,Posts!$R$2:$R$1000,0))&"","") | D53: =IFERROR(INDEX(Posts!$D$2:$D$1000,MATCH($A53,Posts!$R$2:$R$1000,0))&"","") | E53: =IFERROR(IF(INDEX(Posts!$F$2:$F$1000,MATCH($A53,Posts!$R$2:$R$1000,0))="","",INDEX(Posts!$F$2:$F$1000,MATCH($A53,Posts!$R$2:$R$1000,0))),"") | F53: =IFERROR(INDEX(Posts!$G$2:$G$1000,MATCH($A53,Posts!$R$2:$R$1000,0)),"") | G53: =IFERROR(IF(INDEX(Posts!$E$2:$E$1000,MATCH($A53,Posts!$R$2:$R$1000,0))="","",HYPERLINK(INDEX(Posts!$E$2:$E$1000,MATCH($A53,Posts!$R$2:$R$1000,0)))),"")
A54: 9 | B54: =IFERROR(INDEX(Posts!$C$2:$C$1000,MATCH($A54,Posts!$R$2:$R$1000,0))&"","") | C54: =IFERROR(INDEX(Posts!$B$2:$B$1000,MATCH($A54,Posts!$R$2:$R$1000,0))&"","") | D54: =IFERROR(INDEX(Posts!$D$2:$D$1000,MATCH($A54,Posts!$R$2:$R$1000,0))&"","") | E54: =IFERROR(IF(INDEX(Posts!$F$2:$F$1000,MATCH($A54,Posts!$R$2:$R$1000,0))="","",INDEX(Posts!$F$2:$F$1000,MATCH($A54,Posts!$R$2:$R$1000,0))),"") | F54: =IFERROR(INDEX(Posts!$G$2:$G$1000,MATCH($A54,Posts!$R$2:$R$1000,0)),"") | G54: =IFERROR(IF(INDEX(Posts!$E$2:$E$1000,MATCH($A54,Posts!$R$2:$R$1000,0))="","",HYPERLINK(INDEX(Posts!$E$2:$E$1000,MATCH($A54,Posts!$R$2:$R$1000,0)))),"")
A55: 10 | B55: =IFERROR(INDEX(Posts!$C$2:$C$1000,MATCH($A55,Posts!$R$2:$R$1000,0))&"","") | C55: =IFERROR(INDEX(Posts!$B$2:$B$1000,MATCH($A55,Posts!$R$2:$R$1000,0))&"","") | D55: =IFERROR(INDEX(Posts!$D$2:$D$1000,MATCH($A55,Posts!$R$2:$R$1000,0))&"","") | E55: =IFERROR(IF(INDEX(Posts!$F$2:$F$1000,MATCH($A55,Posts!$R$2:$R$1000,0))="","",INDEX(Posts!$F$2:$F$1000,MATCH($A55,Posts!$R$2:$R$1000,0))),"") | F55: =IFERROR(INDEX(Posts!$G$2:$G$1000,MATCH($A55,Posts!$R$2:$R$1000,0)),"") | G55: =IFERROR(IF(INDEX(Posts!$E$2:$E$1000,MATCH($A55,Posts!$R$2:$R$1000,0))="","",HYPERLINK(INDEX(Posts!$E$2:$E$1000,MATCH($A55,Posts!$R$2:$R$1000,0)))),"")
B57: 12-week trend
B58: The 12 weeks up to your latest post. Weeks start on Monday.
B59: Week of | C59: Posts | D59: Views | E59: Avg views
...

Sheet Calendar
A1: Planned date | B1: Song | C1: Section | D1: Take file | E1: Platform(s) | F1: Status | G1: Posted link
A2: 46287 | B2: Song Title | C2: pre-chorus | D2: pre-chorus_08m51s-09m13s.mp4 | E2: TikTok, Instagram, YouTube | F2: Posted | G2: https://www.tiktok.com/@yourhandle/video/0000000000000000022
A3: 46294 | B3: Song Title | C3: chorus | D3: chorus-4_36m02s-36m23s.mp4 | E3: TikTok, Instagram, YouTube | F3: Scheduled
A4: 46294 | B4: Song Title | C4: verse 1 | D4: verse-1b_05m41s-06m00s.mp4 | E4: Instagram trial reel | F4: Edited
A5: 46294 | B5: Song Title | C5: bridge | D5: bridge-2_29m10s-29m38s.mp4 | E5: Instagram trial reel | F5: Edited
A6: 46301 | B6: Second Song | C6: chorus | D6: chorus_02m15s-02m36s.mp4 | E6: TikTok, Instagram, YouTube | F6: Cut
A7: 46301 | B7: Second Song | C7: intro | E7: TikTok, YouTube | F7: Idea

Sheet Lists
A1: Platform | B1: Section | C1: Yes / No | D1: Status | F1: From (s) | G1: Length bucket | I1: These lists feed the dropdowns on Posts and Calendar, and the Review sheet.
A2: Instagram | B2: intro | C2: Yes | D2: Idea | F2: 0 | G2: 0–15 s | I2: Each list has a fixed number of rows: to change a choice, rename it. A row added below a list is not picked up.
A3: TikTok | B3: verse 1 | C3: No | D3: Cut | F3: 15 | G3: 15–25 s | I3: Rename an entry here and the dropdowns follow; posts already logged keep the old name (Find and Replace on Posts).
A4: YouTube | B4: pre-chorus | D4: Edited | F4: 25 | G4: 25–40 s | I4: Review shows the platforms, sections and length buckets listed here; a platform not listed counts as Other.
B5: chorus | D5: Scheduled | F5: 40 | G5: 40+ s | I5: The trial-reel rows on Review look for the names Instagram and Yes, so keep those two as they are.
B6: verse 2 | D6: Posted | I6: Length buckets: a clip goes in the last bucket whose From (s) it reaches.
B7: bridge | I7: Keep From (s) in increasing order.
B8: outro
